[2024-11-15T05:22:41.417+0000] {local_task_job_runner.py:123} INFO - ::group::Pre task execution logs
[2024-11-15T05:22:41.431+0000] {taskinstance.py:2613} INFO - Dependencies all met for dep_context=non-requeueable deps ti=<TaskInstance: fetch_and_store_airbnb_data.fetch_airbnb_data manual__2024-11-15T05:22:38.287816+00:00 [queued]>
[2024-11-15T05:22:41.436+0000] {taskinstance.py:2613} INFO - Dependencies all met for dep_context=requeueable deps ti=<TaskInstance: fetch_and_store_airbnb_data.fetch_airbnb_data manual__2024-11-15T05:22:38.287816+00:00 [queued]>
[2024-11-15T05:22:41.437+0000] {taskinstance.py:2866} INFO - Starting attempt 1 of 2
[2024-11-15T05:22:41.448+0000] {taskinstance.py:2889} INFO - Executing <Task(PythonOperator): fetch_airbnb_data> on 2024-11-15 05:22:38.287816+00:00
[2024-11-15T05:22:41.456+0000] {warnings.py:112} WARNING - /home/***/.local/lib/python3.12/site-packages/***/task/task_runner/standard_task_runner.py:70: DeprecationWarning: This process (pid=133) is multi-threaded, use of fork() may lead to deadlocks in the child.
  pid = os.fork()

[2024-11-15T05:22:41.457+0000] {standard_task_runner.py:104} INFO - Running: ['***', 'tasks', 'run', 'fetch_and_store_airbnb_data', 'fetch_airbnb_data', 'manual__2024-11-15T05:22:38.287816+00:00', '--job-id', '19', '--raw', '--subdir', 'DAGS_FOLDER/dag.py', '--cfg-path', '/tmp/tmp3o56dz9f']
[2024-11-15T05:22:41.457+0000] {standard_task_runner.py:72} INFO - Started process 135 to run task
[2024-11-15T05:22:41.458+0000] {standard_task_runner.py:105} INFO - Job 19: Subtask fetch_airbnb_data
[2024-11-15T05:22:41.654+0000] {task_command.py:467} INFO - Running <TaskInstance: fetch_and_store_airbnb_data.fetch_airbnb_data manual__2024-11-15T05:22:38.287816+00:00 [running]> on host 3331d6fd8766
[2024-11-15T05:22:41.713+0000] {taskinstance.py:3132} INFO - Exporting env vars: AIRFLOW_CTX_DAG_OWNER='***' AIRFLOW_CTX_DAG_ID='fetch_and_store_airbnb_data' AIRFLOW_CTX_TASK_ID='fetch_airbnb_data' AIRFLOW_CTX_EXECUTION_DATE='2024-11-15T05:22:38.287816+00:00' AIRFLOW_CTX_TRY_NUMBER='1' AIRFLOW_CTX_DAG_RUN_ID='manual__2024-11-15T05:22:38.287816+00:00'
[2024-11-15T05:22:41.713+0000] {logging_mixin.py:190} INFO - Task instance is in running state
[2024-11-15T05:22:41.714+0000] {logging_mixin.py:190} INFO -  Previous state of the Task instance: queued
[2024-11-15T05:22:41.714+0000] {logging_mixin.py:190} INFO - Current task name:fetch_airbnb_data state:running start_date:2024-11-15 05:22:41.432163+00:00
[2024-11-15T05:22:41.714+0000] {logging_mixin.py:190} INFO - Dag name:fetch_and_store_airbnb_data and current dag run status:running
[2024-11-15T05:22:41.715+0000] {taskinstance.py:731} INFO - ::endgroup::
[2024-11-15T05:22:42.290+0000] {logging_mixin.py:190} INFO - Attempt 1 failed: 'records'
[2024-11-15T05:22:42.291+0000] {logging_mixin.py:190} INFO - Retrying in 5 seconds...
[2024-11-15T05:22:42.291+0000] {taskinstance.py:3311} ERROR - Task failed with exception
Traceback (most recent call last):
  File "/opt/airflow/dags/dag.py", line 38, in get_airbnb_data
    for record in data['records']
                  ~~~~^^^^^^^^^^^
KeyError: 'records'

During handling of the above exception, another exception occurred:

Traceback (most recent call last):
  File "/home/airflow/.local/lib/python3.12/site-packages/airflow/models/taskinstance.py", line 767, in _execute_task
    result = _execute_callable(context=context, **execute_callable_kwargs)
             ^^^^^^^^^^^^^^^^^^^^^^^^^^^^^^^^^^^^^^^^^^^^^^^^^^^^^^^^^^^^^
  File "/home/airflow/.local/lib/python3.12/site-packages/airflow/models/taskinstance.py", line 733, in _execute_callable
    return ExecutionCallableRunner(
           ^^^^^^^^^^^^^^^^^^^^^^^^
  File "/home/airflow/.local/lib/python3.12/site-packages/airflow/utils/operator_helpers.py", line 252, in run
    return self.func(*args, **kwargs)
           ^^^^^^^^^^^^^^^^^^^^^^^^^^
  File "/home/airflow/.local/lib/python3.12/site-packages/airflow/models/baseoperator.py", line 417, in wrapper
    return func(self, *args, **kwargs)
           ^^^^^^^^^^^^^^^^^^^^^^^^^^^
  File "/home/airflow/.local/lib/python3.12/site-packages/airflow/operators/python.py", line 238, in execute
    return_value = self.execute_callable()
                   ^^^^^^^^^^^^^^^^^^^^^^^
  File "/home/airflow/.local/lib/python3.12/site-packages/airflow/operators/python.py", line 256, in execute_callable
    return runner.run(*self.op_args, **self.op_kwargs)
           ^^^^^^^^^^^^^^^^^^^^^^^^^^^^^^^^^^^^^^^^^^^
  File "/home/airflow/.local/lib/python3.12/site-packages/airflow/utils/operator_helpers.py", line 252, in run
    return self.func(*args, **kwargs)
           ^^^^^^^^^^^^^^^^^^^^^^^^^^
  File "/opt/airflow/dags/dag.py", line 57, in get_airbnb_data
    time.sleep(delay)
    ^^^^
NameError: name 'time' is not defined. Did you forget to import 'time'
[2024-11-15T05:22:42.306+0000] {logging_mixin.py:190} INFO - Task instance in failure state
[2024-11-15T05:22:42.306+0000] {logging_mixin.py:190} INFO - Task start:2024-11-15 05:22:41.432163+00:00 end:2024-11-15 05:22:42.306194+00:00 duration:0.874031
[2024-11-15T05:22:42.307+0000] {logging_mixin.py:190} INFO - Task:<Task(PythonOperator): fetch_airbnb_data> dag:<DAG: fetch_and_store_airbnb_data> dagrun:<DagRun fetch_and_store_airbnb_data @ 2024-11-15 05:22:38.287816+00:00: manual__2024-11-15T05:22:38.287816+00:00, state:running, queued_at: 2024-11-15 05:22:38.302983+00:00. externally triggered: True>
[2024-11-15T05:22:42.307+0000] {logging_mixin.py:190} INFO - Failure caused by name 'time' is not defined
[2024-11-15T05:22:42.307+0000] {taskinstance.py:1225} INFO - Marking task as UP_FOR_RETRY. dag_id=fetch_and_store_airbnb_data, task_id=fetch_airbnb_data, run_id=manual__2024-11-15T05:22:38.287816+00:00, execution_date=20241115T052238, start_date=20241115T052241, end_date=20241115T052242
[2024-11-15T05:22:42.320+0000] {taskinstance.py:340} INFO - ::group::Post task execution logs
[2024-11-15T05:22:42.321+0000] {standard_task_runner.py:124} ERROR - Failed to execute job 19 for task fetch_airbnb_data (name 'time' is not defined; 135)
Traceback (most recent call last):
  File "/opt/airflow/dags/dag.py", line 38, in get_airbnb_data
    for record in data['records']
                  ~~~~^^^^^^^^^^^
KeyError: 'records'

During handling of the above exception, another exception occurred:

Traceback (most recent call last):
  File "/home/airflow/.local/lib/python3.12/site-packages/airflow/task/task_runner/standard_task_runner.py", line 117, in _start_by_fork
    ret = args.func(args, dag=self.dag)
          ^^^^^^^^^^^^^^^^^^^^^^^^^^^^^
  File "/home/airflow/.local/lib/python3.12/site-packages/airflow/cli/cli_config.py", line 49, in command
    return func(*args, **kwargs)
           ^^^^^^^^^^^^^^^^^^^^^
  File "/home/airflow/.local/lib/python3.12/site-packages/airflow/utils/cli.py", line 116, in wrapper
    return f(*args, **kwargs)
           ^^^^^^^^^^^^^^^^^^
  File "/home/airflow/.local/lib/python3.12/site-packages/airflow/cli/commands/task_command.py", line 483, in task_run
    task_return_code = _run_task_by_selected_method(args, _dag, ti)
                       ^^^^^^^^^^^^^^^^^^^^^^^^^^^^^^^^^^^^^^^^^^^^
  File "/home/airflow/.local/lib/python3.12/site-packages/airflow/cli/commands/task_command.py", line 256, in _run_task_by_selected_method
    return _run_raw_task(args, ti)
           ^^^^^^^^^^^^^^^^^^^^^^^
  File "/home/airflow/.local/lib/python3.12/site-packages/airflow/cli/commands/task_command.py", line 341, in _run_raw_task
    return ti._run_raw_task(
           ^^^^^^^^^^^^^^^^^
  File "/home/airflow/.local/lib/python3.12/site-packages/airflow/utils/session.py", line 97, in wrapper
    return func(*args, session=session, **kwargs)
           ^^^^^^^^^^^^^^^^^^^^^^^^^^^^^^^^^^^^^^
  File "/home/airflow/.local/lib/python3.12/site-packages/airflow/models/taskinstance.py", line 3005, in _run_raw_task
    return _run_raw_task(
           ^^^^^^^^^^^^^^
  File "/home/airflow/.local/lib/python3.12/site-packages/airflow/models/taskinstance.py", line 273, in _run_raw_task
    TaskInstance._execute_task_with_callbacks(
  File "/home/airflow/.local/lib/python3.12/site-packages/airflow/models/taskinstance.py", line 3159, in _execute_task_with_callbacks
    result = self._execute_task(context, task_orig)
             ^^^^^^^^^^^^^^^^^^^^^^^^^^^^^^^^^^^^^^
  File "/home/airflow/.local/lib/python3.12/site-packages/airflow/models/taskinstance.py", line 3183, in _execute_task
    return _execute_task(self, context, task_orig)
           ^^^^^^^^^^^^^^^^^^^^^^^^^^^^^^^^^^^^^^^
  File "/home/airflow/.local/lib/python3.12/site-packages/airflow/models/taskinstance.py", line 767, in _execute_task
    result = _execute_callable(context=context, **execute_callable_kwargs)
             ^^^^^^^^^^^^^^^^^^^^^^^^^^^^^^^^^^^^^^^^^^^^^^^^^^^^^^^^^^^^^
  File "/home/airflow/.local/lib/python3.12/site-packages/airflow/models/taskinstance.py", line 733, in _execute_callable
    return ExecutionCallableRunner(
           ^^^^^^^^^^^^^^^^^^^^^^^^
  File "/home/airflow/.local/lib/python3.12/site-packages/airflow/utils/operator_helpers.py", line 252, in run
    return self.func(*args, **kwargs)
           ^^^^^^^^^^^^^^^^^^^^^^^^^^
  File "/home/airflow/.local/lib/python3.12/site-packages/airflow/models/baseoperator.py", line 417, in wrapper
    return func(self, *args, **kwargs)
           ^^^^^^^^^^^^^^^^^^^^^^^^^^^
  File "/home/airflow/.local/lib/python3.12/site-packages/airflow/operators/python.py", line 238, in execute
    return_value = self.execute_callable()
                   ^^^^^^^^^^^^^^^^^^^^^^^
  File "/home/airflow/.local/lib/python3.12/site-packages/airflow/operators/python.py", line 256, in execute_callable
    return runner.run(*self.op_args, **self.op_kwargs)
           ^^^^^^^^^^^^^^^^^^^^^^^^^^^^^^^^^^^^^^^^^^^
  File "/home/airflow/.local/lib/python3.12/site-packages/airflow/utils/operator_helpers.py", line 252, in run
    return self.func(*args, **kwargs)
           ^^^^^^^^^^^^^^^^^^^^^^^^^^
  File "/opt/airflow/dags/dag.py", line 57, in get_airbnb_data
    time.sleep(delay)
    ^^^^
NameError: name 'time' is not defined. Did you forget to import 'time'
[2024-11-15T05:22:42.354+0000] {local_task_job_runner.py:266} INFO - Task exited with return code 1
[2024-11-15T05:22:42.518+0000] {taskinstance.py:3895} INFO - 0 downstream tasks scheduled from follow-on schedule check
[2024-11-15T05:22:42.520+0000] {local_task_job_runner.py:245} INFO - ::endgroup::
