[2024-11-21T01:13:33.980+0000] {local_task_job_runner.py:123} INFO - ::group::Pre task execution logs
[2024-11-21T01:13:33.993+0000] {taskinstance.py:2613} INFO - Dependencies all met for dep_context=non-requeueable deps ti=<TaskInstance: etl_on_airbnb_data.insert_airbnb_data manual__2024-11-21T01:11:36.941414+00:00 [queued]>
[2024-11-21T01:13:33.999+0000] {taskinstance.py:2613} INFO - Dependencies all met for dep_context=requeueable deps ti=<TaskInstance: etl_on_airbnb_data.insert_airbnb_data manual__2024-11-21T01:11:36.941414+00:00 [queued]>
[2024-11-21T01:13:34.000+0000] {taskinstance.py:2866} INFO - Starting attempt 1 of 1
[2024-11-21T01:13:34.010+0000] {taskinstance.py:2889} INFO - Executing <Task(PythonOperator): insert_airbnb_data> on 2024-11-21 01:11:36.941414+00:00
[2024-11-21T01:13:34.018+0000] {warnings.py:112} WARNING - /home/***/.local/lib/python3.12/site-packages/***/task/task_runner/standard_task_runner.py:70: DeprecationWarning: This process (pid=194) is multi-threaded, use of fork() may lead to deadlocks in the child.
  pid = os.fork()

[2024-11-21T01:13:34.019+0000] {standard_task_runner.py:72} INFO - Started process 196 to run task
[2024-11-21T01:13:34.019+0000] {standard_task_runner.py:104} INFO - Running: ['***', 'tasks', 'run', 'etl_on_airbnb_data', 'insert_airbnb_data', 'manual__2024-11-21T01:11:36.941414+00:00', '--job-id', '80', '--raw', '--subdir', 'DAGS_FOLDER/dag.py', '--cfg-path', '/tmp/tmpuvtw4xbt']
[2024-11-21T01:13:34.020+0000] {standard_task_runner.py:105} INFO - Job 80: Subtask insert_airbnb_data
[2024-11-21T01:13:34.052+0000] {task_command.py:467} INFO - Running <TaskInstance: etl_on_airbnb_data.insert_airbnb_data manual__2024-11-21T01:11:36.941414+00:00 [running]> on host 8414eec06bb4
[2024-11-21T01:13:34.103+0000] {taskinstance.py:3132} INFO - Exporting env vars: AIRFLOW_CTX_DAG_OWNER='***' AIRFLOW_CTX_DAG_ID='etl_on_airbnb_data' AIRFLOW_CTX_TASK_ID='insert_airbnb_data' AIRFLOW_CTX_EXECUTION_DATE='2024-11-21T01:11:36.941414+00:00' AIRFLOW_CTX_TRY_NUMBER='1' AIRFLOW_CTX_DAG_RUN_ID='manual__2024-11-21T01:11:36.941414+00:00'
[2024-11-21T01:13:34.104+0000] {logging_mixin.py:190} INFO - Task instance is in running state
[2024-11-21T01:13:34.104+0000] {logging_mixin.py:190} INFO -  Previous state of the Task instance: queued
[2024-11-21T01:13:34.104+0000] {logging_mixin.py:190} INFO - Current task name:insert_airbnb_data state:running start_date:2024-11-21 01:13:33.994229+00:00
[2024-11-21T01:13:34.105+0000] {logging_mixin.py:190} INFO - Dag name:etl_on_airbnb_data and current dag run status:running
[2024-11-21T01:13:34.105+0000] {taskinstance.py:731} INFO - ::endgroup::
[2024-11-21T01:13:34.370+0000] {base.py:84} INFO - Retrieving connection 'airbnb_connection'
[2024-11-21T01:13:34.371+0000] {taskinstance.py:3311} ERROR - Task failed with exception
Traceback (most recent call last):
  File "/home/airflow/.local/lib/python3.12/site-packages/airflow/models/taskinstance.py", line 767, in _execute_task
    result = _execute_callable(context=context, **execute_callable_kwargs)
             ^^^^^^^^^^^^^^^^^^^^^^^^^^^^^^^^^^^^^^^^^^^^^^^^^^^^^^^^^^^^^
  File "/home/airflow/.local/lib/python3.12/site-packages/airflow/models/taskinstance.py", line 733, in _execute_callable
    return ExecutionCallableRunner(
           ^^^^^^^^^^^^^^^^^^^^^^^^
  File "/home/airflow/.local/lib/python3.12/site-packages/airflow/utils/operator_helpers.py", line 252, in run
    return self.func(*args, **kwargs)
           ^^^^^^^^^^^^^^^^^^^^^^^^^^
  File "/home/airflow/.local/lib/python3.12/site-packages/airflow/models/baseoperator.py", line 417, in wrapper
    return func(self, *args, **kwargs)
           ^^^^^^^^^^^^^^^^^^^^^^^^^^^
  File "/home/airflow/.local/lib/python3.12/site-packages/airflow/operators/python.py", line 238, in execute
    return_value = self.execute_callable()
                   ^^^^^^^^^^^^^^^^^^^^^^^
  File "/home/airflow/.local/lib/python3.12/site-packages/airflow/operators/python.py", line 256, in execute_callable
    return runner.run(*self.op_args, **self.op_kwargs)
           ^^^^^^^^^^^^^^^^^^^^^^^^^^^^^^^^^^^^^^^^^^^
  File "/home/airflow/.local/lib/python3.12/site-packages/airflow/utils/operator_helpers.py", line 252, in run
    return self.func(*args, **kwargs)
           ^^^^^^^^^^^^^^^^^^^^^^^^^^
  File "/opt/airflow/dags/dag.py", line 88, in insert_airbnb_data_into_postgres
    postgres_hook.run("""
  File "/home/airflow/.local/lib/python3.12/site-packages/airflow/providers/common/sql/hooks/sql.py", line 485, in run
    with self._create_autocommit_connection(autocommit) as conn:
         ^^^^^^^^^^^^^^^^^^^^^^^^^^^^^^^^^^^^^^^^^^^^^^
  File "/usr/local/lib/python3.12/contextlib.py", line 137, in __enter__
    return next(self.gen)
           ^^^^^^^^^^^^^^
  File "/home/airflow/.local/lib/python3.12/site-packages/airflow/providers/common/sql/hooks/sql.py", line 609, in _create_autocommit_connection
    with closing(self.get_conn()) as conn:
                 ^^^^^^^^^^^^^^^
  File "/home/airflow/.local/lib/python3.12/site-packages/airflow/providers/postgres/hooks/postgres.py", line 181, in get_conn
    self.conn = psycopg2.connect(**conn_args)
                ^^^^^^^^^^^^^^^^^^^^^^^^^^^^^
  File "/home/airflow/.local/lib/python3.12/site-packages/psycopg2/__init__.py", line 122, in connect
    conn = _connect(dsn, connection_factory=connection_factory, **kwasync)
           ^^^^^^^^^^^^^^^^^^^^^^^^^^^^^^^^^^^^^^^^^^^^^^^^^^^^^^^^^^^^^^^
psycopg2.OperationalError: connection to server at "172.18.0.2", port 5433 failed: Connection refused
	Is the server running on that host and accepting TCP/IP connections?

[2024-11-21T01:13:34.381+0000] {logging_mixin.py:190} INFO - Task instance in failure state
[2024-11-21T01:13:34.381+0000] {logging_mixin.py:190} INFO - Task start:2024-11-21 01:13:33.994229+00:00 end:2024-11-21 01:13:34.380829+00:00 duration:0.3866
[2024-11-21T01:13:34.381+0000] {logging_mixin.py:190} INFO - Task:<Task(PythonOperator): insert_airbnb_data> dag:<DAG: etl_on_airbnb_data> dagrun:<DagRun etl_on_airbnb_data @ 2024-11-21 01:11:36.941414+00:00: manual__2024-11-21T01:11:36.941414+00:00, state:running, queued_at: 2024-11-21 01:11:36.948785+00:00. externally triggered: True>
[2024-11-21T01:13:34.382+0000] {logging_mixin.py:190} INFO - Failure caused by connection to server at "172.18.0.2", port 5433 failed: Connection refused
	Is the server running on that host and accepting TCP/IP connections?
[2024-11-21T01:13:34.382+0000] {taskinstance.py:1225} INFO - Marking task as FAILED. dag_id=etl_on_airbnb_data, task_id=insert_airbnb_data, run_id=manual__2024-11-21T01:11:36.941414+00:00, execution_date=20241121T011136, start_date=20241121T011333, end_date=20241121T011334
[2024-11-21T01:13:34.390+0000] {taskinstance.py:340} INFO - ::group::Post task execution logs
[2024-11-21T01:13:34.390+0000] {standard_task_runner.py:124} ERROR - Failed to execute job 80 for task insert_airbnb_data (connection to server at "172.18.0.2", port 5433 failed: Connection refused
	Is the server running on that host and accepting TCP/IP connections?
; 196)
Traceback (most recent call last):
  File "/home/airflow/.local/lib/python3.12/site-packages/airflow/task/task_runner/standard_task_runner.py", line 117, in _start_by_fork
    ret = args.func(args, dag=self.dag)
          ^^^^^^^^^^^^^^^^^^^^^^^^^^^^^
  File "/home/airflow/.local/lib/python3.12/site-packages/airflow/cli/cli_config.py", line 49, in command
    return func(*args, **kwargs)
           ^^^^^^^^^^^^^^^^^^^^^
  File "/home/airflow/.local/lib/python3.12/site-packages/airflow/utils/cli.py", line 116, in wrapper
    return f(*args, **kwargs)
           ^^^^^^^^^^^^^^^^^^
  File "/home/airflow/.local/lib/python3.12/site-packages/airflow/cli/commands/task_command.py", line 483, in task_run
    task_return_code = _run_task_by_selected_method(args, _dag, ti)
                       ^^^^^^^^^^^^^^^^^^^^^^^^^^^^^^^^^^^^^^^^^^^^
  File "/home/airflow/.local/lib/python3.12/site-packages/airflow/cli/commands/task_command.py", line 256, in _run_task_by_selected_method
    return _run_raw_task(args, ti)
           ^^^^^^^^^^^^^^^^^^^^^^^
  File "/home/airflow/.local/lib/python3.12/site-packages/airflow/cli/commands/task_command.py", line 341, in _run_raw_task
    return ti._run_raw_task(
           ^^^^^^^^^^^^^^^^^
  File "/home/airflow/.local/lib/python3.12/site-packages/airflow/utils/session.py", line 97, in wrapper
    return func(*args, session=session, **kwargs)
           ^^^^^^^^^^^^^^^^^^^^^^^^^^^^^^^^^^^^^^
  File "/home/airflow/.local/lib/python3.12/site-packages/airflow/models/taskinstance.py", line 3005, in _run_raw_task
    return _run_raw_task(
           ^^^^^^^^^^^^^^
  File "/home/airflow/.local/lib/python3.12/site-packages/airflow/models/taskinstance.py", line 273, in _run_raw_task
    TaskInstance._execute_task_with_callbacks(
  File "/home/airflow/.local/lib/python3.12/site-packages/airflow/models/taskinstance.py", line 3159, in _execute_task_with_callbacks
    result = self._execute_task(context, task_orig)
             ^^^^^^^^^^^^^^^^^^^^^^^^^^^^^^^^^^^^^^
  File "/home/airflow/.local/lib/python3.12/site-packages/airflow/models/taskinstance.py", line 3183, in _execute_task
    return _execute_task(self, context, task_orig)
           ^^^^^^^^^^^^^^^^^^^^^^^^^^^^^^^^^^^^^^^
  File "/home/airflow/.local/lib/python3.12/site-packages/airflow/models/taskinstance.py", line 767, in _execute_task
    result = _execute_callable(context=context, **execute_callable_kwargs)
             ^^^^^^^^^^^^^^^^^^^^^^^^^^^^^^^^^^^^^^^^^^^^^^^^^^^^^^^^^^^^^
  File "/home/airflow/.local/lib/python3.12/site-packages/airflow/models/taskinstance.py", line 733, in _execute_callable
    return ExecutionCallableRunner(
           ^^^^^^^^^^^^^^^^^^^^^^^^
  File "/home/airflow/.local/lib/python3.12/site-packages/airflow/utils/operator_helpers.py", line 252, in run
    return self.func(*args, **kwargs)
           ^^^^^^^^^^^^^^^^^^^^^^^^^^
  File "/home/airflow/.local/lib/python3.12/site-packages/airflow/models/baseoperator.py", line 417, in wrapper
    return func(self, *args, **kwargs)
           ^^^^^^^^^^^^^^^^^^^^^^^^^^^
  File "/home/airflow/.local/lib/python3.12/site-packages/airflow/operators/python.py", line 238, in execute
    return_value = self.execute_callable()
                   ^^^^^^^^^^^^^^^^^^^^^^^
  File "/home/airflow/.local/lib/python3.12/site-packages/airflow/operators/python.py", line 256, in execute_callable
    return runner.run(*self.op_args, **self.op_kwargs)
           ^^^^^^^^^^^^^^^^^^^^^^^^^^^^^^^^^^^^^^^^^^^
  File "/home/airflow/.local/lib/python3.12/site-packages/airflow/utils/operator_helpers.py", line 252, in run
    return self.func(*args, **kwargs)
           ^^^^^^^^^^^^^^^^^^^^^^^^^^
  File "/opt/airflow/dags/dag.py", line 88, in insert_airbnb_data_into_postgres
    postgres_hook.run("""
  File "/home/airflow/.local/lib/python3.12/site-packages/airflow/providers/common/sql/hooks/sql.py", line 485, in run
    with self._create_autocommit_connection(autocommit) as conn:
         ^^^^^^^^^^^^^^^^^^^^^^^^^^^^^^^^^^^^^^^^^^^^^^
  File "/usr/local/lib/python3.12/contextlib.py", line 137, in __enter__
    return next(self.gen)
           ^^^^^^^^^^^^^^
  File "/home/airflow/.local/lib/python3.12/site-packages/airflow/providers/common/sql/hooks/sql.py", line 609, in _create_autocommit_connection
    with closing(self.get_conn()) as conn:
                 ^^^^^^^^^^^^^^^
  File "/home/airflow/.local/lib/python3.12/site-packages/airflow/providers/postgres/hooks/postgres.py", line 181, in get_conn
    self.conn = psycopg2.connect(**conn_args)
                ^^^^^^^^^^^^^^^^^^^^^^^^^^^^^
  File "/home/airflow/.local/lib/python3.12/site-packages/psycopg2/__init__.py", line 122, in connect
    conn = _connect(dsn, connection_factory=connection_factory, **kwasync)
           ^^^^^^^^^^^^^^^^^^^^^^^^^^^^^^^^^^^^^^^^^^^^^^^^^^^^^^^^^^^^^^^
psycopg2.OperationalError: connection to server at "172.18.0.2", port 5433 failed: Connection refused
	Is the server running on that host and accepting TCP/IP connections?

[2024-11-21T01:13:34.435+0000] {local_task_job_runner.py:266} INFO - Task exited with return code 1
[2024-11-21T01:13:34.447+0000] {taskinstance.py:3895} INFO - 0 downstream tasks scheduled from follow-on schedule check
[2024-11-21T01:13:34.449+0000] {local_task_job_runner.py:245} INFO - ::endgroup::
