[2024-11-21T01:01:28.341+0000] {local_task_job_runner.py:123} INFO - ::group::Pre task execution logs
[2024-11-21T01:01:28.353+0000] {taskinstance.py:2613} INFO - Dependencies all met for dep_context=non-requeueable deps ti=<TaskInstance: scrape_and_store_airbnb_data.insert_airbnb_data manual__2024-11-20T21:29:05.502162+00:00 [queued]>
[2024-11-21T01:01:28.358+0000] {taskinstance.py:2613} INFO - Dependencies all met for dep_context=requeueable deps ti=<TaskInstance: scrape_and_store_airbnb_data.insert_airbnb_data manual__2024-11-20T21:29:05.502162+00:00 [queued]>
[2024-11-21T01:01:28.359+0000] {taskinstance.py:2866} INFO - Starting attempt 3 of 3
[2024-11-21T01:01:28.368+0000] {taskinstance.py:2889} INFO - Executing <Task(PythonOperator): insert_airbnb_data> on 2024-11-20 21:29:05.502162+00:00
[2024-11-21T01:01:28.376+0000] {warnings.py:112} WARNING - /home/***/.local/lib/python3.12/site-packages/***/task/task_runner/standard_task_runner.py:70: DeprecationWarning: This process (pid=231) is multi-threaded, use of fork() may lead to deadlocks in the child.
  pid = os.fork()

[2024-11-21T01:01:28.377+0000] {standard_task_runner.py:72} INFO - Started process 233 to run task
[2024-11-21T01:01:28.377+0000] {standard_task_runner.py:104} INFO - Running: ['***', 'tasks', 'run', 'scrape_and_store_airbnb_data', 'insert_airbnb_data', 'manual__2024-11-20T21:29:05.502162+00:00', '--job-id', '73', '--raw', '--subdir', 'DAGS_FOLDER/dag.py', '--cfg-path', '/tmp/tmp3novv85b']
[2024-11-21T01:01:28.378+0000] {standard_task_runner.py:105} INFO - Job 73: Subtask insert_airbnb_data
[2024-11-21T01:01:28.409+0000] {task_command.py:467} INFO - Running <TaskInstance: scrape_and_store_airbnb_data.insert_airbnb_data manual__2024-11-20T21:29:05.502162+00:00 [running]> on host b3a8bb7dbe23
[2024-11-21T01:01:28.461+0000] {taskinstance.py:3132} INFO - Exporting env vars: AIRFLOW_CTX_DAG_OWNER='***' AIRFLOW_CTX_DAG_ID='scrape_and_store_airbnb_data' AIRFLOW_CTX_TASK_ID='insert_airbnb_data' AIRFLOW_CTX_EXECUTION_DATE='2024-11-20T21:29:05.502162+00:00' AIRFLOW_CTX_TRY_NUMBER='3' AIRFLOW_CTX_DAG_RUN_ID='manual__2024-11-20T21:29:05.502162+00:00'
[2024-11-21T01:01:28.462+0000] {logging_mixin.py:190} INFO - Task instance is in running state
[2024-11-21T01:01:28.462+0000] {logging_mixin.py:190} INFO -  Previous state of the Task instance: queued
[2024-11-21T01:01:28.463+0000] {logging_mixin.py:190} INFO - Current task name:insert_airbnb_data state:running start_date:2024-11-21 01:01:28.353970+00:00
[2024-11-21T01:01:28.463+0000] {logging_mixin.py:190} INFO - Dag name:scrape_and_store_airbnb_data and current dag run status:running
[2024-11-21T01:01:28.463+0000] {taskinstance.py:731} INFO - ::endgroup::
[2024-11-21T01:01:28.726+0000] {base.py:84} INFO - Retrieving connection 'airbnb_connection'
[2024-11-21T01:01:28.727+0000] {taskinstance.py:3311} ERROR - Task failed with exception
Traceback (most recent call last):
  File "/home/airflow/.local/lib/python3.12/site-packages/airflow/models/taskinstance.py", line 767, in _execute_task
    result = _execute_callable(context=context, **execute_callable_kwargs)
             ^^^^^^^^^^^^^^^^^^^^^^^^^^^^^^^^^^^^^^^^^^^^^^^^^^^^^^^^^^^^^
  File "/home/airflow/.local/lib/python3.12/site-packages/airflow/models/taskinstance.py", line 733, in _execute_callable
    return ExecutionCallableRunner(
           ^^^^^^^^^^^^^^^^^^^^^^^^
  File "/home/airflow/.local/lib/python3.12/site-packages/airflow/utils/operator_helpers.py", line 252, in run
    return self.func(*args, **kwargs)
           ^^^^^^^^^^^^^^^^^^^^^^^^^^
  File "/home/airflow/.local/lib/python3.12/site-packages/airflow/models/baseoperator.py", line 417, in wrapper
    return func(self, *args, **kwargs)
           ^^^^^^^^^^^^^^^^^^^^^^^^^^^
  File "/home/airflow/.local/lib/python3.12/site-packages/airflow/operators/python.py", line 238, in execute
    return_value = self.execute_callable()
                   ^^^^^^^^^^^^^^^^^^^^^^^
  File "/home/airflow/.local/lib/python3.12/site-packages/airflow/operators/python.py", line 256, in execute_callable
    return runner.run(*self.op_args, **self.op_kwargs)
           ^^^^^^^^^^^^^^^^^^^^^^^^^^^^^^^^^^^^^^^^^^^
  File "/home/airflow/.local/lib/python3.12/site-packages/airflow/utils/operator_helpers.py", line 252, in run
    return self.func(*args, **kwargs)
           ^^^^^^^^^^^^^^^^^^^^^^^^^^
  File "/opt/airflow/dags/dag.py", line 88, in insert_airbnb_data_into_postgres
    postgres_hook.run("""
  File "/home/airflow/.local/lib/python3.12/site-packages/airflow/providers/common/sql/hooks/sql.py", line 485, in run
    with self._create_autocommit_connection(autocommit) as conn:
         ^^^^^^^^^^^^^^^^^^^^^^^^^^^^^^^^^^^^^^^^^^^^^^
  File "/usr/local/lib/python3.12/contextlib.py", line 137, in __enter__
    return next(self.gen)
           ^^^^^^^^^^^^^^
  File "/home/airflow/.local/lib/python3.12/site-packages/airflow/providers/common/sql/hooks/sql.py", line 609, in _create_autocommit_connection
    with closing(self.get_conn()) as conn:
                 ^^^^^^^^^^^^^^^
  File "/home/airflow/.local/lib/python3.12/site-packages/airflow/providers/postgres/hooks/postgres.py", line 181, in get_conn
    self.conn = psycopg2.connect(**conn_args)
                ^^^^^^^^^^^^^^^^^^^^^^^^^^^^^
  File "/home/airflow/.local/lib/python3.12/site-packages/psycopg2/__init__.py", line 122, in connect
    conn = _connect(dsn, connection_factory=connection_factory, **kwasync)
           ^^^^^^^^^^^^^^^^^^^^^^^^^^^^^^^^^^^^^^^^^^^^^^^^^^^^^^^^^^^^^^^
psycopg2.OperationalError: connection to server at "172.18.0.2", port 5433 failed: Connection refused
	Is the server running on that host and accepting TCP/IP connections?

[2024-11-21T01:01:28.736+0000] {logging_mixin.py:190} INFO - Task instance in failure state
[2024-11-21T01:01:28.736+0000] {logging_mixin.py:190} INFO - Task start:2024-11-21 01:01:28.353970+00:00 end:2024-11-21 01:01:28.735958+00:00 duration:0.381988
[2024-11-21T01:01:28.737+0000] {logging_mixin.py:190} INFO - Task:<Task(PythonOperator): insert_airbnb_data> dag:<DAG: scrape_and_store_airbnb_data> dagrun:<DagRun scrape_and_store_airbnb_data @ 2024-11-20 21:29:05.502162+00:00: manual__2024-11-20T21:29:05.502162+00:00, state:running, queued_at: 2024-11-21 00:59:35.501194+00:00. externally triggered: True>
[2024-11-21T01:01:28.737+0000] {logging_mixin.py:190} INFO - Failure caused by connection to server at "172.18.0.2", port 5433 failed: Connection refused
	Is the server running on that host and accepting TCP/IP connections?
[2024-11-21T01:01:28.738+0000] {taskinstance.py:1225} INFO - Marking task as FAILED. dag_id=scrape_and_store_airbnb_data, task_id=insert_airbnb_data, run_id=manual__2024-11-20T21:29:05.502162+00:00, execution_date=20241120T212905, start_date=20241121T010128, end_date=20241121T010128
[2024-11-21T01:01:28.748+0000] {taskinstance.py:340} INFO - ::group::Post task execution logs
[2024-11-21T01:01:28.749+0000] {standard_task_runner.py:124} ERROR - Failed to execute job 73 for task insert_airbnb_data (connection to server at "172.18.0.2", port 5433 failed: Connection refused
	Is the server running on that host and accepting TCP/IP connections?
; 233)
Traceback (most recent call last):
  File "/home/airflow/.local/lib/python3.12/site-packages/airflow/task/task_runner/standard_task_runner.py", line 117, in _start_by_fork
    ret = args.func(args, dag=self.dag)
          ^^^^^^^^^^^^^^^^^^^^^^^^^^^^^
  File "/home/airflow/.local/lib/python3.12/site-packages/airflow/cli/cli_config.py", line 49, in command
    return func(*args, **kwargs)
           ^^^^^^^^^^^^^^^^^^^^^
  File "/home/airflow/.local/lib/python3.12/site-packages/airflow/utils/cli.py", line 116, in wrapper
    return f(*args, **kwargs)
           ^^^^^^^^^^^^^^^^^^
  File "/home/airflow/.local/lib/python3.12/site-packages/airflow/cli/commands/task_command.py", line 483, in task_run
    task_return_code = _run_task_by_selected_method(args, _dag, ti)
                       ^^^^^^^^^^^^^^^^^^^^^^^^^^^^^^^^^^^^^^^^^^^^
  File "/home/airflow/.local/lib/python3.12/site-packages/airflow/cli/commands/task_command.py", line 256, in _run_task_by_selected_method
    return _run_raw_task(args, ti)
           ^^^^^^^^^^^^^^^^^^^^^^^
  File "/home/airflow/.local/lib/python3.12/site-packages/airflow/cli/commands/task_command.py", line 341, in _run_raw_task
    return ti._run_raw_task(
           ^^^^^^^^^^^^^^^^^
  File "/home/airflow/.local/lib/python3.12/site-packages/airflow/utils/session.py", line 97, in wrapper
    return func(*args, session=session, **kwargs)
           ^^^^^^^^^^^^^^^^^^^^^^^^^^^^^^^^^^^^^^
  File "/home/airflow/.local/lib/python3.12/site-packages/airflow/models/taskinstance.py", line 3005, in _run_raw_task
    return _run_raw_task(
           ^^^^^^^^^^^^^^
  File "/home/airflow/.local/lib/python3.12/site-packages/airflow/models/taskinstance.py", line 273, in _run_raw_task
    TaskInstance._execute_task_with_callbacks(
  File "/home/airflow/.local/lib/python3.12/site-packages/airflow/models/taskinstance.py", line 3159, in _execute_task_with_callbacks
    result = self._execute_task(context, task_orig)
             ^^^^^^^^^^^^^^^^^^^^^^^^^^^^^^^^^^^^^^
  File "/home/airflow/.local/lib/python3.12/site-packages/airflow/models/taskinstance.py", line 3183, in _execute_task
    return _execute_task(self, context, task_orig)
           ^^^^^^^^^^^^^^^^^^^^^^^^^^^^^^^^^^^^^^^
  File "/home/airflow/.local/lib/python3.12/site-packages/airflow/models/taskinstance.py", line 767, in _execute_task
    result = _execute_callable(context=context, **execute_callable_kwargs)
             ^^^^^^^^^^^^^^^^^^^^^^^^^^^^^^^^^^^^^^^^^^^^^^^^^^^^^^^^^^^^^
  File "/home/airflow/.local/lib/python3.12/site-packages/airflow/models/taskinstance.py", line 733, in _execute_callable
    return ExecutionCallableRunner(
           ^^^^^^^^^^^^^^^^^^^^^^^^
  File "/home/airflow/.local/lib/python3.12/site-packages/airflow/utils/operator_helpers.py", line 252, in run
    return self.func(*args, **kwargs)
           ^^^^^^^^^^^^^^^^^^^^^^^^^^
  File "/home/airflow/.local/lib/python3.12/site-packages/airflow/models/baseoperator.py", line 417, in wrapper
    return func(self, *args, **kwargs)
           ^^^^^^^^^^^^^^^^^^^^^^^^^^^
  File "/home/airflow/.local/lib/python3.12/site-packages/airflow/operators/python.py", line 238, in execute
    return_value = self.execute_callable()
                   ^^^^^^^^^^^^^^^^^^^^^^^
  File "/home/airflow/.local/lib/python3.12/site-packages/airflow/operators/python.py", line 256, in execute_callable
    return runner.run(*self.op_args, **self.op_kwargs)
           ^^^^^^^^^^^^^^^^^^^^^^^^^^^^^^^^^^^^^^^^^^^
  File "/home/airflow/.local/lib/python3.12/site-packages/airflow/utils/operator_helpers.py", line 252, in run
    return self.func(*args, **kwargs)
           ^^^^^^^^^^^^^^^^^^^^^^^^^^
  File "/opt/airflow/dags/dag.py", line 88, in insert_airbnb_data_into_postgres
    postgres_hook.run("""
  File "/home/airflow/.local/lib/python3.12/site-packages/airflow/providers/common/sql/hooks/sql.py", line 485, in run
    with self._create_autocommit_connection(autocommit) as conn:
         ^^^^^^^^^^^^^^^^^^^^^^^^^^^^^^^^^^^^^^^^^^^^^^
  File "/usr/local/lib/python3.12/contextlib.py", line 137, in __enter__
    return next(self.gen)
           ^^^^^^^^^^^^^^
  File "/home/airflow/.local/lib/python3.12/site-packages/airflow/providers/common/sql/hooks/sql.py", line 609, in _create_autocommit_connection
    with closing(self.get_conn()) as conn:
                 ^^^^^^^^^^^^^^^
  File "/home/airflow/.local/lib/python3.12/site-packages/airflow/providers/postgres/hooks/postgres.py", line 181, in get_conn
    self.conn = psycopg2.connect(**conn_args)
                ^^^^^^^^^^^^^^^^^^^^^^^^^^^^^
  File "/home/airflow/.local/lib/python3.12/site-packages/psycopg2/__init__.py", line 122, in connect
    conn = _connect(dsn, connection_factory=connection_factory, **kwasync)
           ^^^^^^^^^^^^^^^^^^^^^^^^^^^^^^^^^^^^^^^^^^^^^^^^^^^^^^^^^^^^^^^
psycopg2.OperationalError: connection to server at "172.18.0.2", port 5433 failed: Connection refused
	Is the server running on that host and accepting TCP/IP connections?

[2024-11-21T01:01:28.792+0000] {local_task_job_runner.py:266} INFO - Task exited with return code 1
[2024-11-21T01:01:28.804+0000] {taskinstance.py:3895} INFO - 0 downstream tasks scheduled from follow-on schedule check
[2024-11-21T01:01:28.807+0000] {local_task_job_runner.py:245} INFO - ::endgroup::
